
Warning: PATH set to RVM ruby but GEM_HOME and/or GEM_PATH not set, see:
    https://github.com/rvm/rvm/issues/3212

[lin777@Evelyn-Arch ~]$ cd pr
practicaDjango/ prueba1.py      
[lin777@Evelyn-Arch ~]$ cd practicaDjango/
[lin777@Evelyn-Arch practicaDjango]$ cd theproject/
[lin777@Evelyn-Arch theproject]$ python manege.py runserver
python: can't open file 'manege.py': [Errno 2] No such file or directory
[lin777@Evelyn-Arch theproject]$ python manage.py runserver 
Performing system checks...

System check identified no issues (0 silenced).

You have 14 unapplied migration(s). Your project may not work properly until you apply the migrations for app(s): admin, auth, contenttypes, sessions.
Run 'python manage.py migrate' to apply them.

April 14, 2018 - 20:40:29
Django version 2.0.1, using settings 'theproject.settings'
Starting development server at http://127.0.0.1:8000/
Quit the server with CONTROL-C.
^C[lin777@Evelyn-Arch theproject]$ python manage.py migrate  
Operations to perform:
  Apply all migrations: admin, auth, contenttypes, sessions
Running migrations:
  Applying contenttypes.0001_initial... OK
  Applying auth.0001_initial... OK
  Applying admin.0001_initial... OK
  Applying admin.0002_logentry_remove_auto_add... OK
  Applying contenttypes.0002_remove_content_type_name... OK
  Applying auth.0002_alter_permission_name_max_length... OK
  Applying auth.0003_alter_user_email_max_length... OK
  Applying auth.0004_alter_user_username_opts... OK
  Applying auth.0005_alter_user_last_login_null... OK
  Applying auth.0006_require_contenttypes_0002... OK
  Applying auth.0007_alter_validators_add_error_messages... OK
  Applying auth.0008_alter_user_username_max_length... OK
  Applying auth.0009_alter_user_last_name_max_length... OK
  Applying sessions.0001_initial... OK
[lin777@Evelyn-Arch theproject]$ python manage.py runserver
Performing system checks...

System check identified no issues (0 silenced).
April 14, 2018 - 20:40:55
Django version 2.0.1, using settings 'theproject.settings'
Starting development server at http://127.0.0.1:8000/
Quit the server with CONTROL-C.
Not Found: /
[14/Apr/2018 20:41:10] "GET / HTTP/1.1" 404 2080
Not Found: /favicon.ico
[14/Apr/2018 20:41:10] "GET /favicon.ico HTTP/1.1" 404 2131
Not Found: /favicon.ico
[14/Apr/2018 20:41:10] "GET /favicon.ico HTTP/1.1" 404 2131
[14/Apr/2018 20:41:18] "GET /profile HTTP/1.1" 301 0
[14/Apr/2018 20:41:18] "GET /profile/ HTTP/1.1" 200 34
Performing system checks...

System check identified no issues (0 silenced).
April 14, 2018 - 20:41:40
Django version 2.0.1, using settings 'theproject.settings'
Starting development server at http://127.0.0.1:8000/
Quit the server with CONTROL-C.
Performing system checks...

System check identified no issues (0 silenced).
April 14, 2018 - 20:41:50
Django version 2.0.1, using settings 'theproject.settings'
Starting development server at http://127.0.0.1:8000/
Quit the server with CONTROL-C.
Performing system checks...

System check identified no issues (0 silenced).
April 14, 2018 - 20:42:02
Django version 2.0.1, using settings 'theproject.settings'
Starting development server at http://127.0.0.1:8000/
Quit the server with CONTROL-C.
[14/Apr/2018 20:42:31] "GET /profile/pusheen/ HTTP/1.1" 200 34
Not Found: /profile/
[14/Apr/2018 20:43:01] "GET /profile/ HTTP/1.1" 404 2139
[14/Apr/2018 20:43:06] "GET /profile/pusheen/ HTTP/1.1" 200 34
Performing system checks...

System check identified no issues (0 silenced).
April 14, 2018 - 20:43:25
Django version 2.0.1, using settings 'theproject.settings'
Starting development server at http://127.0.0.1:8000/
Quit the server with CONTROL-C.
[14/Apr/2018 20:43:31] "GET /profile/pusheen/ HTTP/1.1" 200 54
[14/Apr/2018 20:43:49] "GET /profile/amorcito/ HTTP/1.1" 200 55
Performing system checks...

System check identified no issues (0 silenced).
April 14, 2018 - 20:44:33
Django version 2.0.1, using settings 'theproject.settings'
Starting development server at http://127.0.0.1:8000/
Quit the server with CONTROL-C.
Performing system checks...

System check identified no issues (0 silenced).
April 14, 2018 - 20:45:02
Django version 2.0.1, using settings 'theproject.settings'
Starting development server at http://127.0.0.1:8000/
Quit the server with CONTROL-C.
[14/Apr/2018 20:45:08] "GET /profile/ HTTP/1.1" 200 59
Performing system checks...

System check identified no issues (0 silenced).
April 14, 2018 - 20:45:47
Django version 2.0.1, using settings 'theproject.settings'
Starting development server at http://127.0.0.1:8000/
Quit the server with CONTROL-C.
Performing system checks...

System check identified no issues (0 silenced).
April 14, 2018 - 20:46:14
Django version 2.0.1, using settings 'theproject.settings'
Starting development server at http://127.0.0.1:8000/
Quit the server with CONTROL-C.
Performing system checks...

System check identified no issues (0 silenced).
April 14, 2018 - 20:46:34
Django version 2.0.1, using settings 'theproject.settings'
Starting development server at http://127.0.0.1:8000/
Quit the server with CONTROL-C.
Not Found: /profile/pusheen
[14/Apr/2018 20:47:55] "GET /profile/pusheen HTTP/1.1" 404 2319
Not Found: /profile/pusheen/
[14/Apr/2018 20:48:00] "GET /profile/pusheen/ HTTP/1.1" 404 2322
[14/Apr/2018 20:48:06] "GET /profile/5/ HTTP/1.1" 200 48
[14/Apr/2018 20:48:10] "GET /profile/ HTTP/1.1" 200 59
Performing system checks...

System check identified no issues (0 silenced).
April 14, 2018 - 20:49:02
Django version 2.0.1, using settings 'theproject.settings'
Starting development server at http://127.0.0.1:8000/
Quit the server with CONTROL-C.
Internal Server Error: /profile/pusheen
Traceback (most recent call last):
  File "/usr/lib/python3.6/site-packages/django/core/handlers/exception.py", line 35, in inner
    response = get_response(request)
  File "/usr/lib/python3.6/site-packages/django/core/handlers/base.py", line 128, in _get_response
    response = self.process_exception_by_middleware(e, request)
  File "/usr/lib/python3.6/site-packages/django/core/handlers/base.py", line 126, in _get_response
    response = wrapped_callback(request, *callback_args, **callback_kwargs)
TypeError: profile() got an unexpected keyword argument 'article'
[14/Apr/2018 20:49:16] "GET /profile/pusheen HTTP/1.1" 500 61163
Performing system checks...

Unhandled exception in thread started by <function check_errors.<locals>.wrapper at 0x7fa92e5356a8>
Traceback (most recent call last):
  File "/usr/lib/python3.6/site-packages/django/utils/autoreload.py", line 225, in wrapper
    fn(*args, **kwargs)
  File "/usr/lib/python3.6/site-packages/django/core/management/commands/runserver.py", line 121, in inner_run
    self.check(display_num_errors=True)
  File "/usr/lib/python3.6/site-packages/django/core/management/base.py", line 364, in check
    include_deployment_checks=include_deployment_checks,
  File "/usr/lib/python3.6/site-packages/django/core/management/base.py", line 351, in _run_checks
    return checks.run_checks(**kwargs)
  File "/usr/lib/python3.6/site-packages/django/core/checks/registry.py", line 73, in run_checks
    new_errors = check(app_configs=app_configs)
  File "/usr/lib/python3.6/site-packages/django/core/checks/urls.py", line 13, in check_url_config
    return check_resolver(resolver)
  File "/usr/lib/python3.6/site-packages/django/core/checks/urls.py", line 23, in check_resolver
    return check_method()
  File "/usr/lib/python3.6/site-packages/django/urls/resolvers.py", line 397, in check
    for pattern in self.url_patterns:
  File "/usr/lib/python3.6/site-packages/django/utils/functional.py", line 36, in __get__
    res = instance.__dict__[self.name] = self.func(instance)
  File "/usr/lib/python3.6/site-packages/django/urls/resolvers.py", line 536, in url_patterns
    patterns = getattr(self.urlconf_module, "urlpatterns", self.urlconf_module)
  File "/usr/lib/python3.6/site-packages/django/utils/functional.py", line 36, in __get__
    res = instance.__dict__[self.name] = self.func(instance)
  File "/usr/lib/python3.6/site-packages/django/urls/resolvers.py", line 529, in urlconf_module
    return import_module(self.urlconf_name)
  File "/usr/lib/python3.6/importlib/__init__.py", line 126, in import_module
    return _bootstrap._gcd_import(name[level:], package, level)
  File "<frozen importlib._bootstrap>", line 994, in _gcd_import
  File "<frozen importlib._bootstrap>", line 971, in _find_and_load
  File "<frozen importlib._bootstrap>", line 955, in _find_and_load_unlocked
  File "<frozen importlib._bootstrap>", line 665, in _load_unlocked
  File "<frozen importlib._bootstrap_external>", line 678, in exec_module
  File "<frozen importlib._bootstrap>", line 219, in _call_with_frames_removed
  File "/home/lin777/practicaDjango/theproject/theproject/urls.py", line 21, in <module>
    path('', include('urlexample.urls'))
  File "/usr/lib/python3.6/site-packages/django/urls/conf.py", line 34, in include
    urlconf_module = import_module(urlconf_module)
  File "/usr/lib/python3.6/importlib/__init__.py", line 126, in import_module
    return _bootstrap._gcd_import(name[level:], package, level)
  File "<frozen importlib._bootstrap>", line 994, in _gcd_import
  File "<frozen importlib._bootstrap>", line 971, in _find_and_load
  File "<frozen importlib._bootstrap>", line 955, in _find_and_load_unlocked
  File "<frozen importlib._bootstrap>", line 665, in _load_unlocked
  File "<frozen importlib._bootstrap_external>", line 678, in exec_module
  File "<frozen importlib._bootstrap>", line 219, in _call_with_frames_removed
  File "/home/lin777/practicaDjango/theproject/urlexample/urls.py", line 2, in <module>
    from . import views
  File "/home/lin777/practicaDjango/theproject/urlexample/views.py", line 3
    def profile(request, username="Default user", article):
               ^
SyntaxError: non-default argument follows default argument
Performing system checks...

System check identified no issues (0 silenced).
April 14, 2018 - 20:49:54
Django version 2.0.1, using settings 'theproject.settings'
Starting development server at http://127.0.0.1:8000/
Quit the server with CONTROL-C.
[14/Apr/2018 20:49:59] "GET /profile/pusheen HTTP/1.1" 200 59
Performing system checks...

System check identified no issues (0 silenced).
April 14, 2018 - 20:50:28
Django version 2.0.1, using settings 'theproject.settings'
Starting development server at http://127.0.0.1:8000/
Quit the server with CONTROL-C.
Performing system checks...

Unhandled exception in thread started by <function check_errors.<locals>.wrapper at 0x7f5b749e26a8>
Traceback (most recent call last):
  File "/usr/lib/python3.6/site-packages/django/utils/autoreload.py", line 225, in wrapper
    fn(*args, **kwargs)
  File "/usr/lib/python3.6/site-packages/django/core/management/commands/runserver.py", line 121, in inner_run
    self.check(display_num_errors=True)
  File "/usr/lib/python3.6/site-packages/django/core/management/base.py", line 364, in check
    include_deployment_checks=include_deployment_checks,
  File "/usr/lib/python3.6/site-packages/django/core/management/base.py", line 351, in _run_checks
    return checks.run_checks(**kwargs)
  File "/usr/lib/python3.6/site-packages/django/core/checks/registry.py", line 73, in run_checks
    new_errors = check(app_configs=app_configs)
  File "/usr/lib/python3.6/site-packages/django/core/checks/urls.py", line 13, in check_url_config
    return check_resolver(resolver)
  File "/usr/lib/python3.6/site-packages/django/core/checks/urls.py", line 23, in check_resolver
    return check_method()
  File "/usr/lib/python3.6/site-packages/django/urls/resolvers.py", line 397, in check
    for pattern in self.url_patterns:
  File "/usr/lib/python3.6/site-packages/django/utils/functional.py", line 36, in __get__
    res = instance.__dict__[self.name] = self.func(instance)
  File "/usr/lib/python3.6/site-packages/django/urls/resolvers.py", line 536, in url_patterns
    patterns = getattr(self.urlconf_module, "urlpatterns", self.urlconf_module)
  File "/usr/lib/python3.6/site-packages/django/utils/functional.py", line 36, in __get__
    res = instance.__dict__[self.name] = self.func(instance)
  File "/usr/lib/python3.6/site-packages/django/urls/resolvers.py", line 529, in urlconf_module
    return import_module(self.urlconf_name)
  File "/usr/lib/python3.6/importlib/__init__.py", line 126, in import_module
    return _bootstrap._gcd_import(name[level:], package, level)
  File "<frozen importlib._bootstrap>", line 994, in _gcd_import
  File "<frozen importlib._bootstrap>", line 971, in _find_and_load
  File "<frozen importlib._bootstrap>", line 955, in _find_and_load_unlocked
  File "<frozen importlib._bootstrap>", line 665, in _load_unlocked
  File "<frozen importlib._bootstrap_external>", line 678, in exec_module
  File "<frozen importlib._bootstrap>", line 219, in _call_with_frames_removed
  File "/home/lin777/practicaDjango/theproject/theproject/urls.py", line 21, in <module>
    path('', include('urlexample.urls'))
  File "/usr/lib/python3.6/site-packages/django/urls/conf.py", line 34, in include
    urlconf_module = import_module(urlconf_module)
  File "/usr/lib/python3.6/importlib/__init__.py", line 126, in import_module
    return _bootstrap._gcd_import(name[level:], package, level)
  File "<frozen importlib._bootstrap>", line 994, in _gcd_import
  File "<frozen importlib._bootstrap>", line 971, in _find_and_load
  File "<frozen importlib._bootstrap>", line 955, in _find_and_load_unlocked
  File "<frozen importlib._bootstrap>", line 665, in _load_unlocked
  File "<frozen importlib._bootstrap_external>", line 678, in exec_module
  File "<frozen importlib._bootstrap>", line 219, in _call_with_frames_removed
  File "/home/lin777/practicaDjango/theproject/urlexample/urls.py", line 2, in <module>
    from . import views
  File "/home/lin777/practicaDjango/theproject/urlexample/views.py", line 7
    
    ^
SyntaxError: unexpected EOF while parsing
Performing system checks...

System check identified no issues (0 silenced).
April 14, 2018 - 20:51:32
Django version 2.0.1, using settings 'theproject.settings'
Starting development server at http://127.0.0.1:8000/
Quit the server with CONTROL-C.
Performing system checks...

System check identified no issues (0 silenced).
April 14, 2018 - 20:51:35
Django version 2.0.1, using settings 'theproject.settings'
Starting development server at http://127.0.0.1:8000/
Quit the server with CONTROL-C.
Performing system checks...

Unhandled exception in thread started by <function check_errors.<locals>.wrapper at 0x7f3098f576a8>
Traceback (most recent call last):
  File "/usr/lib/python3.6/site-packages/django/utils/autoreload.py", line 225, in wrapper
    fn(*args, **kwargs)
  File "/usr/lib/python3.6/site-packages/django/core/management/commands/runserver.py", line 121, in inner_run
    self.check(display_num_errors=True)
  File "/usr/lib/python3.6/site-packages/django/core/management/base.py", line 364, in check
    include_deployment_checks=include_deployment_checks,
  File "/usr/lib/python3.6/site-packages/django/core/management/base.py", line 351, in _run_checks
    return checks.run_checks(**kwargs)
  File "/usr/lib/python3.6/site-packages/django/core/checks/registry.py", line 73, in run_checks
    new_errors = check(app_configs=app_configs)
  File "/usr/lib/python3.6/site-packages/django/core/checks/urls.py", line 13, in check_url_config
    return check_resolver(resolver)
  File "/usr/lib/python3.6/site-packages/django/core/checks/urls.py", line 23, in check_resolver
    return check_method()
  File "/usr/lib/python3.6/site-packages/django/urls/resolvers.py", line 397, in check
    for pattern in self.url_patterns:
  File "/usr/lib/python3.6/site-packages/django/utils/functional.py", line 36, in __get__
    res = instance.__dict__[self.name] = self.func(instance)
  File "/usr/lib/python3.6/site-packages/django/urls/resolvers.py", line 536, in url_patterns
    patterns = getattr(self.urlconf_module, "urlpatterns", self.urlconf_module)
  File "/usr/lib/python3.6/site-packages/django/utils/functional.py", line 36, in __get__
    res = instance.__dict__[self.name] = self.func(instance)
  File "/usr/lib/python3.6/site-packages/django/urls/resolvers.py", line 529, in urlconf_module
    return import_module(self.urlconf_name)
  File "/usr/lib/python3.6/importlib/__init__.py", line 126, in import_module
    return _bootstrap._gcd_import(name[level:], package, level)
  File "<frozen importlib._bootstrap>", line 994, in _gcd_import
  File "<frozen importlib._bootstrap>", line 971, in _find_and_load
  File "<frozen importlib._bootstrap>", line 955, in _find_and_load_unlocked
  File "<frozen importlib._bootstrap>", line 665, in _load_unlocked
  File "<frozen importlib._bootstrap_external>", line 678, in exec_module
  File "<frozen importlib._bootstrap>", line 219, in _call_with_frames_removed
  File "/home/lin777/practicaDjango/theproject/theproject/urls.py", line 21, in <module>
    path('', include('urlexample.urls'))
  File "/usr/lib/python3.6/site-packages/django/urls/conf.py", line 34, in include
    urlconf_module = import_module(urlconf_module)
  File "/usr/lib/python3.6/importlib/__init__.py", line 126, in import_module
    return _bootstrap._gcd_import(name[level:], package, level)
  File "<frozen importlib._bootstrap>", line 994, in _gcd_import
  File "<frozen importlib._bootstrap>", line 971, in _find_and_load
  File "<frozen importlib._bootstrap>", line 955, in _find_and_load_unlocked
  File "<frozen importlib._bootstrap>", line 665, in _load_unlocked
  File "<frozen importlib._bootstrap_external>", line 678, in exec_module
  File "<frozen importlib._bootstrap>", line 219, in _call_with_frames_removed
  File "/home/lin777/practicaDjango/theproject/urlexample/urls.py", line 8, in <module>
    path('profile/<slug:article>', views.article()),
TypeError: article() missing 2 required positional arguments: 'requset' and 'article'
Performing system checks...

System check identified no issues (0 silenced).
April 14, 2018 - 20:52:11
Django version 2.0.1, using settings 'theproject.settings'
Starting development server at http://127.0.0.1:8000/
Quit the server with CONTROL-C.
[14/Apr/2018 20:52:14] "GET /profile/pusheen HTTP/1.1" 200 37
[14/Apr/2018 20:52:56] "GET /profile/45 HTTP/1.1" 200 32
Performing system checks...

System check identified no issues (0 silenced).
April 14, 2018 - 20:53:16
Django version 2.0.1, using settings 'theproject.settings'
Starting development server at http://127.0.0.1:8000/
Quit the server with CONTROL-C.
[14/Apr/2018 20:53:20] "GET /profile/45/ HTTP/1.1" 200 49
Performing system checks...

System check identified no issues (0 silenced).
April 14, 2018 - 20:54:07
Django version 2.0.1, using settings 'theproject.settings'
Starting development server at http://127.0.0.1:8000/
Quit the server with CONTROL-C.
[14/Apr/2018 20:54:10] "GET /profile/45/ HTTP/1.1" 200 49
[14/Apr/2018 20:54:13] "GET /profile/45/ HTTP/1.1" 200 49
[14/Apr/2018 20:54:25] "GET /profile/4 HTTP/1.1" 200 31
[14/Apr/2018 20:54:29] "GET /profile/58 HTTP/1.1" 200 32
[14/Apr/2018 20:54:33] "GET /profile/pusheen HTTP/1.1" 200 37
Performing system checks...

System check identified no issues (0 silenced).
April 14, 2018 - 20:55:08
Django version 2.0.1, using settings 'theproject.settings'
Starting development server at http://127.0.0.1:8000/
Quit the server with CONTROL-C.
Performing system checks...

System check identified no issues (0 silenced).
April 14, 2018 - 20:56:42
Django version 2.0.1, using settings 'theproject.settings'
Starting development server at http://127.0.0.1:8000/
Quit the server with CONTROL-C.
Performing system checks...

System check identified no issues (0 silenced).
April 14, 2018 - 20:57:40
Django version 2.0.1, using settings 'theproject.settings'
Starting development server at http://127.0.0.1:8000/
Quit the server with CONTROL-C.
[14/Apr/2018 20:57:55] "GET /profile/28/ HTTP/1.1" 200 59
^C[lin777@Evelyn-Arch theproject]$ cd ..
[lin777@Evelyn-Arch practicaDjango]$ django-admin startproject queryng-one-to-many
CommandError: 'queryng-one-to-many' is not a valid project name. Please make sure the name is a valid identifier.
[lin777@Evelyn-Arch practicaDjango]$ django-admin startproject queryngonetomany   
[lin777@Evelyn-Arch practicaDjango]$ cd queryngonetomany/
[lin777@Evelyn-Arch queryngonetomany]$ ls
manage.py  queryngonetomany
[lin777@Evelyn-Arch queryngonetomany]$ cd queryngonetomany/
[lin777@Evelyn-Arch queryngonetomany]$ ls
__init__.py  settings.py  urls.py  wsgi.py
[lin777@Evelyn-Arch queryngonetomany]$ cd ..
[lin777@Evelyn-Arch queryngonetomany]$ python manage.py startapp onetomany
[lin777@Evelyn-Arch queryngonetomany]$ python manage.py makemigrations   
No changes detected
[lin777@Evelyn-Arch queryngonetomany]$ python manage.py makemigrations
Migrations for 'onetomany':
  onetomany/migrations/0001_initial.py
    - Create model Course
    - Create model Lecture
    - Create model Section
    - Add field section to lecture
[lin777@Evelyn-Arch queryngonetomany]$ python manage.py migrate       
Operations to perform:
  Apply all migrations: admin, auth, contenttypes, onetomany, sessions
Running migrations:
  Applying contenttypes.0001_initial... OK
  Applying auth.0001_initial... OK
  Applying admin.0001_initial... OK
  Applying admin.0002_logentry_remove_auto_add... OK
  Applying contenttypes.0002_remove_content_type_name... OK
  Applying auth.0002_alter_permission_name_max_length... OK
  Applying auth.0003_alter_user_email_max_length... OK
  Applying auth.0004_alter_user_username_opts... OK
  Applying auth.0005_alter_user_last_login_null... OK
  Applying auth.0006_require_contenttypes_0002... OK
  Applying auth.0007_alter_validators_add_error_messages... OK
  Applying auth.0008_alter_user_username_max_length... OK
  Applying auth.0009_alter_user_last_name_max_length... OK
  Applying onetomany.0001_initial... OK
  Applying sessions.0001_initial... OK
[lin777@Evelyn-Arch queryngonetomany]$ python manage.py shell  
Python 3.6.4 (default, Jan  5 2018, 02:35:40) 
Type 'copyright', 'credits' or 'license' for more information
IPython 6.1.0 -- An enhanced Interactive Python. Type '?' for help.

In [1]: from onetomany.models import Course, Section, Lecture

In [2]: intro = Course(title="Intro a la progra", slug="-----")

In [3]: intro.save()

In [4]: section(course=1, title="Declaracion de variables", order=1)
--------------------------------------------------------------------------
NameError                                Traceback (most recent call last)
<ipython-input-4-e4db6632811a> in <module>()
----> 1 section(course=1, title="Declaracion de variables", order=1)

NameError: name 'section' is not defined

In [5]: section = Section(course=1, title="Declaracion de variables", orde
   ...: r=1)
--------------------------------------------------------------------------
ValueError                               Traceback (most recent call last)
<ipython-input-5-05c83b0d7a32> in <module>()
----> 1 section = Section(course=1, title="Declaracion de variables", order=1)

/usr/lib/python3.6/site-packages/django/db/models/base.py in __init__(self, *args, **kwargs)                                                        
    475                 # checked) by the RelatedObjectDescriptor.
    476                 if rel_obj is not _DEFERRED:
--> 477                     _setattr(self, field.name, rel_obj)
    478             else:
    479                 if val is not _DEFERRED:

/usr/lib/python3.6/site-packages/django/db/models/fields/related_descriptors.py in __set__(self, instance, value)
    195                     instance._meta.object_name,
    196                     self.field.name,
--> 197                     self.field.remote_field.model._meta.object_name,
    198                 )
    199             )

ValueError: Cannot assign "1": "Section.course" must be a "Course" instance.

In [6]: section = Section(course=intro, title="Declaracion de variables", 
   ...: order=1)

In [7]: section2 = Section(course=intro, title="Generacion de funciones", 
   ...: order=2)

In [8]: section3 = Section(course=intro, title="Creacion de clases", order
   ...: =3)

In [9]: section.save()

In [10]: section2.save()

In [11]: section3.save()

In [12]: lectura1 = Lecture(section=section, title="Tipos de dato", order=
    ...: 1, code_link="----", slug="---")

In [13]: lectura2 = Lecture(section=section, title="Declarar variables", o
    ...: rder=1, code_link="----", slug="---")

In [14]: lectura3 = Lecture(section=section, title="Instanciar variables",
    ...:  order=2, code_link="----", slug="---")

In [15]: lectura1.save()

In [16]: lectura2.save()

In [17]: lectura3.save()

In [18]: from onetomany.models import Course, Section, Lecture

In [19]: Course.objects.filter(title="Intro a la progra")
Out[19]: <QuerySet [<Course: Intro a la progra>]>

In [20]: intro = Course.objects.get(title="Intro a la progra")

In [21]: intro.section_set.all()
Out[21]: <QuerySet [<Section: Declaracion de variables>, <Section: Generacion de funciones>, <Section: Creacion de clases>]>

In [22]: section = Section.objects.get(title="Declaracion de variables")

In [23]: section.lecture_set.all()
Out[23]: <QuerySet [<Lecture: Tipos de dato>, <Lecture: Declarar variables>, <Lecture: Instanciar variables>]>

In [24]: Lecture.objects.filter(section__course__title="Intro a la progra"
    ...: )
Out[24]: <QuerySet [<Lecture: Tipos de dato>, <Lecture: Declarar variables>, <Lecture: Instanciar variables>]>

In [25]: Course.objects.filter(section__title='Declaracion de variables')
Out[25]: <QuerySet [<Course: Intro a la progra>]>

In [26]: Course.objects.filter(section__lecture__title='Tipos de dato')
Out[26]: <QuerySet [<Course: Intro a la progra>]>

In [27]: 
